I'm sorry, but an uncaught exception occurred.

While running game code:
  File "game/script.rpy", line 7, in script
    e "Вы создали новую игру Ren'Py."
Exception: Sayer 'e' is not defined.

-- Full Traceback ------------------------------------------------------------

Full traceback:
  File "game/script.rpy", line 7, in script
    e "Вы создали новую игру Ren'Py."
  File "/home/dmitrii/renpy-8.2.1-sdk/renpy/ast.py", line 2557, in execute
    Say.execute(self)
  File "/home/dmitrii/renpy-8.2.1-sdk/renpy/ast.py", line 575, in execute
    who = eval_who(self.who, self.who_fast)
  File "/home/dmitrii/renpy-8.2.1-sdk/renpy/ast.py", line 464, in eval_who
    raise Exception("Sayer '%s' is not defined." % who)
Exception: Sayer 'e' is not defined.

Linux-5.15.0-71-generic-x86_64-with-glibc2.35 x86_64
Ren'Py 8.2.1.24030407
Однажды в деревне! 1.0
Mon Aug 12 14:07:15 2024
